<?xml version="1.0" encoding="UTF-8"?>
<!-- Generated by org.testng.reporters.JUnitReportReporter -->
<testsuite skipped="3" hostname="BGLRT49500328" name="com.qa.TestScripts.TC11_12_RetryAnalyzer" tests="5" failures="0" timestamp="19 Nov 2021 10:00:08 GMT" time="7.494" errors="1">
  <testcase name="LogInToApp" time="7.480" classname="com.qa.TestScripts.TC11_12_RetryAnalyzer"/>
  <testcase name="method1" time="0.002" classname="com.qa.TestScripts.TC11_12_RetryAnalyzer">
    <skipped/>
  </testcase> <!-- method1 -->
  <testcase name="method1" time="0.004" classname="com.qa.TestScripts.TC11_12_RetryAnalyzer">
    <error type="java.lang.NullPointerException">
      <![CDATA[java.lang.NullPointerException
	at com.qa.TestScripts.TC11_12_RetryAnalyzer.method1(TC11_12_RetryAnalyzer.java:61)
	at sun.reflect.NativeMethodAccessorImpl.invoke0(Native Method)
	at sun.reflect.NativeMethodAccessorImpl.invoke(Unknown Source)
	at sun.reflect.DelegatingMethodAccessorImpl.invoke(Unknown Source)
	at java.lang.reflect.Method.invoke(Unknown Source)
	at org.testng.internal.MethodInvocationHelper.invokeMethod(MethodInvocationHelper.java:100)
	at org.testng.internal.Invoker.invokeMethod(Invoker.java:646)
	at org.testng.internal.Invoker.retryFailed(Invoker.java:958)
	at org.testng.internal.Invoker.invokeTestMethods(Invoker.java:1160)
	at org.testng.internal.TestMethodWorker.invokeTestMethods(TestMethodWorker.java:129)
	at org.testng.internal.TestMethodWorker.run(TestMethodWorker.java:112)
	at org.testng.TestRunner.privateRun(TestRunner.java:753)
	at org.testng.TestRunner.run(TestRunner.java:607)
	at org.testng.SuiteRunner.runTest(SuiteRunner.java:368)
	at org.testng.SuiteRunner.runSequentially(SuiteRunner.java:363)
	at org.testng.SuiteRunner.privateRun(SuiteRunner.java:321)
	at org.testng.SuiteRunner.run(SuiteRunner.java:270)
	at org.testng.SuiteRunnerWorker.runSuite(SuiteRunnerWorker.java:52)
	at org.testng.SuiteRunnerWorker.run(SuiteRunnerWorker.java:86)
	at org.testng.TestNG.runSuitesSequentially(TestNG.java:1284)
	at org.testng.TestNG.runSuitesLocally(TestNG.java:1209)
	at org.testng.TestNG.runSuites(TestNG.java:1124)
	at org.testng.TestNG.run(TestNG.java:1096)
	at org.testng.remote.AbstractRemoteTestNG.run(AbstractRemoteTestNG.java:132)
	at org.testng.remote.RemoteTestNG.initAndRun(RemoteTestNG.java:236)
	at org.testng.remote.RemoteTestNG.main(RemoteTestNG.java:81)
]]>
    </error>
  </testcase> <!-- method1 -->
  <testcase name="method1" time="0.003" classname="com.qa.TestScripts.TC11_12_RetryAnalyzer">
    <skipped/>
  </testcase> <!-- method1 -->
  <testcase name="method1" time="0.005" classname="com.qa.TestScripts.TC11_12_RetryAnalyzer">
    <skipped/>
  </testcase> <!-- method1 -->
</testsuite> <!-- com.qa.TestScripts.TC11_12_RetryAnalyzer -->
